Workbook

Sheet XYZ_RAW
A1: Month | B1: Business_Unit | C1: Department | D1: Account_Category | E1: Account_Name | F1: Amount_INR_Lakh | G1: Actual_Budget_Status | H1: Source_Owner | I1: Remarks
A2: Apr-2026 | B2: Software Solutions | C2: Engineering | D2: Revenue | E2: Software Subscription Revenue | F2: 320 | G2: Actual | H2: Finance | I2: Monthly close data
A3: Apr-2026 | B3: Data Analytics | C3: Delivery | D3: Revenue | E3: Analytics Services Revenue | F3: 205 | G3: Actual | H3: Finance | I3: Monthly close data
A4: Apr-2026 | B4: Cloud Services | C4: Cloud Operations | D4: Revenue | E4: Cloud Services Revenue | F4: 125 | G4: Actual | H4: Finance | I4: Monthly close data
A5: Apr-2026 | B5: Corporate | C5: Human Resources | D5: Operating Expense | E5: Employee Cost | F5: 250 | G5: Actual | H5: Finance | I5: Payroll and benefits
A6: Apr-2026 | B6: Corporate | C6: Facilities | D6: Operating Expense | E6: Rent and Utilities | F6: 48 | G6: Actual | H6: Finance | I6: Office-related expenses
A7: Apr-2026 | B7: Corporate | C7: IT | D7: Operating Expense | E7: Software Licenses | F7: 28 | G7: Actual | H7: Finance | I7: Annual and monthly licenses
A8: Apr-2026 | B8: Corporate | C8: Sales | D8: Operating Expense | E8: Travel and Sales Expense | F8: 18 | G8: Actual | H8: Finance | I8: Sales travel and events
A9: Apr-2026 | B9: Corporate | C9: Finance | D9: Operating Expense | E9: Other Administrative Expenses | F9: 22 | G9: Actual | H9: Finance | I9: General administration
A10: Apr-2026 | B10: Corporate | C10: Finance | D10: Other | E10: Depreciation | F10: 17 | G10: Actual | H10: Finance | I10: Fixed asset depreciation
A11: Apr-2026 | B11: Corporate | C11: Treasury | D11: Other | E11: Interest Expense | F11: 9 | G11: Actual | H11: Finance | I11: Borrowing cost
A12: May-2026 | B12: Software Solutions | C12: Engineering | D12: Revenue | E12: Software Subscription Revenue | F12: 335 | G12: Actual | H12: Finance | I12: Monthly close data
A13: May-2026 | B13: Data Analytics | C13: Delivery | D13: Revenue | E13: Analytics Services Revenue | F13: 210 | G13: Actual | H13: Finance | I13: Monthly close data
... A121: Mar-2027 | B121: Corporate | C121: Treasury | D121: Other | E121: Interest Expense | F121: 9 | G121: Actual | H121: Finance | I121: Illustrative monthly actual

Sheet Data_Validation
A1: Check ID | B1: What we check in Raw_Actuals | C1: Why? | D1: Result
A2: V001 | B2: Total number of records | C2: To check whether data is complete | D2: =ROWS(Raw_Actuals[#Data]) -> 120
A3: V002 | B3: Blank cells | C3: To find missing information | D3: =COUNTBLANK(Raw_Actuals[Month]) -> 0
A4: V003 | B4: Duplicate records | C4: To prevent double-counting | D4: =ROWS(Raw_Actuals[#Data])-ROWS(_xlfn.UNIQUE(Raw_Actuals[#Data])) -> 0
A5: V004 | B5: Available months | C5: To check whether all 12 months exist | D5: =COUNTA(_xlfn.UNIQUE(Raw_Actuals[Month])) -> 12
A6: V005 | B6: Actual/Budget status | C6: To ensure we are using actual data | D6: =COUNTA(_xlfn.UNIQUE(Raw_Actuals[Actual_Budget_Status])) -> 1
A7: V006 | B7: Currency units | C7: To avoid mixing ₹ lakh and ₹ crore | D7: INR Lakh
A8: V007 | B8: Negative amounts | C8: To identify refunds or errors | D8: =COUNTIF(Raw_Actuals[Amount_INR_Lakh],"<0") -> 0
A9: V008 | B9: Account categories | C9: To ensure correct classification | D9: =COUNTA(_xlfn.UNIQUE(Raw_Actuals[Account_Category])) -> 3

Sheet Data_Profiling
A1: Metric | B1: Values
A2: Total Revenue | B2: =SUMIFS(Raw_Actuals[Amount_INR_Lakh],Raw_Actuals[Account_Category],"Revenue") -> 9143 | D2: Profitability Metric | E2: Amount (₹ lakh) | F2: Margin % | G2: Business Unit | H2: Revenue (₹ lakh) | I2: Revenue Contribution %
A3: Total Operating Expenses | B3: =SUMIFS(Raw_Actuals[Amount_INR_Lakh],Raw_Actuals[Account_Category],"Operating Expense") -> 4695 | D3: Revenue | E3: =B2 -> 9143 | F3: =E3/$E$3 -> 1 | G3: Software Solutions | H3: =SUMIFS(Raw_Actuals[Amount_INR_Lakh],Raw_Actuals[Business_Unit],G3,Raw_Actuals[Account_Category],"Revenue") -> 4520 | I3: =H3/$B$2 -> 0.49436728
A4: Software Solutions Revenue | B4: =SUMIFS(Raw_Actuals[Amount_INR_Lakh],Raw_Actuals[Business_Unit],"Software Solutions",Raw_Actuals[Account_Category],"Revenue") -> 4520 | D4: EBITDA | E4: =B53 -> 4448 | F4: =E4/$E$3 -> 0.4864924 | G4: Data Analytics | H4: =SUMIFS(Raw_Actuals[Amount_INR_Lakh],Raw_Actuals[Business_Unit],G4,Raw_Actuals[Account_Category],"Revenue") -> 2783 | I4: =H4/$B$2 -> 0.30438587
A5: Software Solutions Revenue % | B5: =B4/B2 -> 0.49436728 | D5: EBIT | E5: =B56 -> 4244 | F5: =E5/$E$3 -> 0.46418025 | G5: Cloud Services | H5: =SUMIFS(Raw_Actuals[Amount_INR_Lakh],Raw_Actuals[Business_Unit],G5,Raw_Actuals[Account_Category],"Revenue") -> 1840 | I5: =H5/$B$2 -> 0.20124686
A6: Data Analytics Revenue | B6: =SUMIFS(Raw_Actuals[Amount_INR_Lakh],Raw_Actuals[Business_Unit],"Data Analytics",Raw_Actuals[Account_Category],"Revenue") -> 2783 | D6: PBT | E6: =B58 -> 4136 | F6: =E6/$E$3 -> 0.45236793
A7: Data Analytics Revenue % | B7: =B6/B2 -> 0.30438587 | D7: Net Profit | E7: =B62 -> 3102 | F7: =E7/$E$3 -> 0.33927595 | G7: Business Unit Revenue Reconciliation | H7: =SUM(H3:H5)-$B$2 -> 0
A8: Cloud Services Revenue | B8: =SUMIFS(Raw_Actuals[Amount_INR_Lakh],Raw_Actuals[Business_Unit],"Cloud Services",Raw_Actuals[Account_Category],"Revenue") -> 1840
A9: Cloud Services Revenue % | B9: =B8/B2 -> 0.20124686
A10: Revenue Reconciliation Check | B10: =SUM(B4,B6,B8)-B2 -> 0
A13: Monthly Revenue Trend
A14: Month | B14: Revenue (₹ lakh) | C14: MoM Growth %
A15: =DATE(2026,4,1) -> 46113 | B15: =SUMIFS(Raw_Actuals[Amount_INR_Lakh],Raw_Actuals[Month],$A15,Raw_Actuals[Account_Category],"Revenue") -> 650
A16: =EDATE(A15,1) -> 46143 | B16: =SUMIFS(Raw_Actuals[Amount_INR_Lakh],Raw_Actuals[Month],$A16,Raw_Actuals[Account_Category],"Revenue") -> 675 | C16: =(B16-B15)/B15 -> 0.038461538
A17: =EDATE(A16,1) -> 46174 | B17: =SUMIFS(Raw_Actuals[Amount_INR_Lakh],Raw_Actuals[Month],$A17,Raw_Actuals[Account_Category],"Revenue") -> 698 | C17: =(B17-B16)/B16 -> 0.034074074
A18: =EDATE(A17,1) -> 46204 | B18: =SUMIFS(Raw_Actuals[Amount_INR_Lakh],Raw_Actuals[Month],$A18,Raw_Actuals[Account_Category],"Revenue") -> 710 | C18: =(B18-B17)/B17 -> 0.017191977
A19: =EDATE(A18,1) -> 46235 | B19: =SUMIFS(Raw_Actuals[Amount_INR_Lakh],Raw_Actuals[Month],$A19,Raw_Actuals[Account_Category],"Revenue") -> 727 | C19: =(B19-B18)/B18 -> 0.023943662
A20: =EDATE(A19,1) -> 46266 | B20: =SUMIFS(Raw_Actuals[Amount_INR_Lakh],Raw_Actuals[Month],$A20,Raw_Actuals[Account_Category],"Revenue") -> 748 | C20: =(B20-B19)/B19 -> 0.028885832 | G20: Business Unit | H20: Revenue (₹ lakh) | I20: Allocated OpEx (₹ lakh) | J20: EBITDA (₹ lakh) | K20: EBITDA Margin %
A21: =EDATE(A20,1) -> 46296 | B21: =SUMIFS(Raw_Actuals[Amount_INR_Lakh],Raw_Actuals[Month],$A21,Raw_Actuals[Account_Category],"Revenue") -> 767 | C21: =(B21-B20)/B20 -> 0.02540107 | G21: Software Solutions | H21: =SUMIFS(Raw_Actuals[Amount_INR_Lakh],Raw_Actuals[Business_Unit],G21,Raw_Actuals[Account_Category],"Revenue") -> 4520 | I21: =$B$3*(H21/$B$2) -> 2321.0544 | J21: =H21-I21 -> 2198.9456 | K21: =J21/H21 -> 0.4864924
A22: =EDATE(A21,1) -> 46327 | B22: =SUMIFS(Raw_Actuals[Amount_INR_Lakh],Raw_Actuals[Month],$A22,Raw_Actuals[Account_Category],"Revenue") -> 788 | C22: =(B22-B21)/B21 -> 0.0273794 | G22: Data Analytics | H22: =SUMIFS(Raw_Actuals[Amount_INR_Lakh],Raw_Actuals[Business_Unit],G22,Raw_Actuals[Account_Category],"Revenue") -> 2783 | I22: =$B$3*(H22/$B$2) -> 1429.0917 | J22: =H22-I22 -> 1353.9083 | K22: =J22/H22 -> 0.4864924
A23: =EDATE(A22,1) -> 46357 | B23: =SUMIFS(Raw_Actuals[Amount_INR_Lakh],Raw_Actuals[Month],$A23,Raw_Actuals[Account_Category],"Revenue") -> 810 | C23: =(B23-B22)/B22 -> 0.027918782 | G23: Cloud Services | H23: =SUMIFS(Raw_Actuals[Amount_INR_Lakh],Raw_Actuals[Business_Unit],G23,Raw_Actuals[Account_Category],"Revenue") -> 1840 | I23: =$B$3*(H23/$B$2) -> 944.85399 | J23: =H23-I23 -> 895.14601 | K23: =J23/H23 -> 0.4864924
A24: =EDATE(A23,1) -> 46388 | B24: =SUMIFS(Raw_Actuals[Amount_INR_Lakh],Raw_Actuals[Month],$A24,Raw_Actuals[Account_Category],"Revenue") -> 830 | C24: =(B24-B23)/B23 -> 0.024691358
A25: =EDATE(A24,1) -> 46419 | B25: =SUMIFS(Raw_Actuals[Amount_INR_Lakh],Raw_Actuals[Month],$A25,Raw_Actuals[Account_Category],"Revenue") -> 850 | C25: =(B25-B24)/B24 -> 0.024096386 | H25: Business-Unit EBITDA Reconciliation | I25: =SUM(J21:J23)-$B$53 -> 0
A26: =EDATE(A25,1) -> 46447 | B26: =SUMIFS(Raw_Actuals[Amount_INR_Lakh],Raw_Actuals[Month],$A26,Raw_Actuals[Account_Category],"Revenue") -> 890 | C26: =(B26-B25)/B25 -> 0.047058824
A28: Annual Revenue Reconciliation | B28: =SUM(B15:B26)-B2 -> 0
A30: Average Monthly Revenue | B30: =AVERAGE(B15:B26) -> 761.91667
A31: Highest Monthly Revenue | B31: =MAX(B15:B26) -> 890
A32: Lowest Monthly Revenue | B32: =MIN(B15:B26) -> 650
A33: Revenue Range | B33: =B31-B32 -> 240
A34: Revenue Standard Deviation | B34: =_xlfn.STDEV.S(B15:B26) -> 73.910829
A35: Revenue Coefficient of Variation | B35: =B34/B30 -> 0.097006447
A36: Total Revenue (₹ crore) | B36: =B2/100 -> 91.43
A38: Total Employee Cost | B38: =SUMIFS(Raw_Actuals[Amount_INR_Lakh],Raw_Actuals[Account_Name],"Employee Cost") -> 3169
A39: Employee Cost % of Revenue | B39: =B38/B2 -> 0.34660396
A40: Total Rent and Utilities | B40: =SUMIFS(Raw_Actuals[Amount_INR_Lakh],Raw_Actuals[Account_Name],"Rent and Utilities") -> 588
A41: Rent and Utilities % of Revenue | B41: =B40/B2 -> 0.064311495
A42: Total Software Licenses | B42: =SUMIFS(Raw_Actuals[Amount_INR_Lakh],Raw_Actuals[Account_Name],"Software Licenses") -> 374
A43: Software Licenses % of Revenue | B43: =B42/B2 -> 0.040905611
A44: Total Travel and Sales Expense | B44: =SUMIFS(Raw_Actuals[Amount_INR_Lakh],Raw_Actuals[Account_Name],"Travel and Sales Expense") -> 285
A45: Travel and Sales Expense % of Revenue | B45: =B44/B2 -> 0.031171388 | G45: Account Name | H45: Annual Actual (₹ lakh)
...

Sheet Budget_Assumptions
A1: Budget Assumption | B1: Value | C1: Unit | D1: Explanation
A2: Revenue Growth | B2: 0.12 | C2: % | D2: Expected annual revenue growth
A3: Employee Cost Growth | B3: 0.1 | C3: % | D3: Expected increase in employee costs
A4: Rent and Utilities Growth | B4: 0.06 | C4: % | D4: Expected increase in rent and utilities
A5: Software Licenses Growth | B5: 0.08 | C5: % | D5: Expected increase in software license costs
A6: Travel and Sales Expense Growth | B6: 0.15 | C6: % | D6: Expected increase in travel and sales expenses
A7: Other Administrative Expense Growth | B7: 0.07 | C7: % | D7: Expected increase in administrative expenses
A8: Tax Rate | B8: 0.25 | C8: % | D8: Assumed tax rate for budgeting

Sheet FY2027_Budget
A1: Month | B1: Revenue Budget (₹ lakh) | C1: Employee Cost Budget (₹ lakh) | D1: Rent & Utilities Budget (₹ lakh) | E1: Software Licenses Budget (₹ lakh) | F1: Travel & Sales Budget (₹ lakh) | G1: Other Admin Budget (₹ lakh) | H1: Total OpEx Budget (₹ lakh) | I1: EBITDA Budget (₹ lakh) | J1: EBITDA Margin %
A2: 46504 | B2: =Data_Profiling!B15*(1+Budget_Assumptions!$B$2) -> 728 | C2: {=SUMPRODUCT((TEXT(Raw_Actuals[Month],"mmm-yy")=TEXT(EDATE(A2,-12),"mmm-yy"))*(Raw_Actuals[Account_Name]="Employee Cost")*Raw_Actuals[Amount_INR_Lakh])*(1+Budget_Assumptions!$B$3)} -> 275 | D2: =Data_Profiling!H53*(1+Budget_Assumptions!$B$4) -> 50.88 | E2: =Data_Profiling!H68*(1+Budget_Assumptions!$B$5) -> 30.24 | F2: =Data_Profiling!H83*(1+Budget_Assumptions!$B$6) -> 20.7 | G2: =Data_Profiling!H98*(1+Budget_Assumptions!$B$7) -> 23.54 | H2: =SUM(C2:G2) -> 400.36 | I2: =B2-H2 -> 327.64 | J2: =I2/B2 -> 0.45005495
A3: 46534 | B3: =Data_Profiling!B16*(1+Budget_Assumptions!$B$2) -> 756 | C3: {=SUMPRODUCT((TEXT(Raw_Actuals[Month],"mmm-yy")=TEXT(EDATE(A3,-12),"mmm-yy"))*(Raw_Actuals[Account_Name]="Employee Cost")*Raw_Actuals[Amount_INR_Lakh])*(1+Budget_Assumptions!$B$3)} -> 277.2 | D3: =Data_Profiling!H54*(1+Budget_Assumptions!$B$4) -> 50.88 | E3: =Data_Profiling!H69*(1+Budget_Assumptions!$B$5) -> 31.32 | F3: =Data_Profiling!H84*(1+Budget_Assumptions!$B$6) -> 23 | G3: =Data_Profiling!H99*(1+Budget_Assumptions!$B$7) -> 22.47 | H3: =SUM(C3:G3) -> 404.87 | I3: =B3-H3 -> 351.13 | J3: =I3/B3 -> 0.46445767
A4: 46565 | B4: =Data_Profiling!B17*(1+Budget_Assumptions!$B$2) -> 781.76 | C4: {=SUMPRODUCT((TEXT(Raw_Actuals[Month],"mmm-yy")=TEXT(EDATE(A4,-12),"mmm-yy"))*(Raw_Actuals[Account_Name]="Employee Cost")*Raw_Actuals[Amount_INR_Lakh])*(1+Budget_Assumptions!$B$3)} -> 280.5 | D4: =Data_Profiling!H55*(1+Budget_Assumptions!$B$4) -> 50.88 | E4: =Data_Profiling!H70*(1+Budget_Assumptions!$B$5) -> 33.48 | F4: =Data_Profiling!H85*(1+Budget_Assumptions!$B$6) -> 27.6 | G4: =Data_Profiling!H100*(1+Budget_Assumptions!$B$7) -> 24.61 | H4: =SUM(C4:G4) -> 417.07 | I4: =B4-H4 -> 364.69 | J4: =I4/B4 -> 0.46649867
A5: 46595 | B5: =Data_Profiling!B18*(1+Budget_Assumptions!$B$2) -> 795.2 | C5: {=SUMPRODUCT((TEXT(Raw_Actuals[Month],"mmm-yy")=TEXT(EDATE(A5,-12),"mmm-yy"))*(Raw_Actuals[Account_Name]="Employee Cost")*Raw_Actuals[Amount_INR_Lakh])*(1+Budget_Assumptions!$B$3)} -> 283.8 | D5: =Data_Profiling!H56*(1+Budget_Assumptions!$B$4) -> 50.88 | E5: =Data_Profiling!H71*(1+Budget_Assumptions!$B$5) -> 32.4 | F5: =Data_Profiling!H86*(1+Budget_Assumptions!$B$6) -> 25.3 | G5: =Data_Profiling!H101*(1+Budget_Assumptions!$B$7) -> 23.54 | H5: =SUM(C5:G5) -> 415.92 | I5: =B5-H5 -> 379.28 | J5: =I5/B5 -> 0.47696177
A6: 46626 | B6: =Data_Profiling!B19*(1+Budget_Assumptions!$B$2) -> 814.24 | C6: {=SUMPRODUCT((TEXT(Raw_Actuals[Month],"mmm-yy")=TEXT(EDATE(A6,-12),"mmm-yy"))*(Raw_Actuals[Account_Name]="Employee Cost")*Raw_Actuals[Amount_INR_Lakh])*(1+Budget_Assumptions!$B$3)} -> 286 | D6: =Data_Profiling!H57*(1+Budget_Assumptions!$B$4) -> 50.88 | E6: =Data_Profiling!H72*(1+Budget_Assumptions!$B$5) -> 32.4 | F6: =Data_Profiling!H87*(1+Budget_Assumptions!$B$6) -> 26.45 | G6: =Data_Profiling!H102*(1+Budget_Assumptions!$B$7) -> 24.61 | H6: =SUM(C6:G6) -> 420.34 | I6: =B6-H6 -> 393.9 | J6: =I6/B6 -> 0.483764
A7: 46657 | B7: =Data_Profiling!B20*(1+Budget_Assumptions!$B$2) -> 837.76 | C7: {=SUMPRODUCT((TEXT(Raw_Actuals[Month],"mmm-yy")=TEXT(EDATE(A7,-12),"mmm-yy"))*(Raw_Actuals[Account_Name]="Employee Cost")*Raw_Actuals[Amount_INR_Lakh])*(1+Budget_Assumptions!$B$3)} -> 288.2 | D7: =Data_Profiling!H58*(1+Budget_Assumptions!$B$4) -> 51.94 | E7: =Data_Profiling!H73*(1+Budget_Assumptions!$B$5) -> 33.48 | F7: =Data_Profiling!H88*(1+Budget_Assumptions!$B$6) -> 27.6 | G7: =Data_Profiling!H103*(1+Budget_Assumptions!$B$7) -> 23.54 | H7: =SUM(C7:G7) -> 424.76 | I7: =B7-H7 -> 413 | J7: =I7/B7 -> 0.49298128
A8: 46687 | B8: =Data_Profiling!B21*(1+Budget_Assumptions!$B$2) -> 859.04 | C8: {=SUMPRODUCT((TEXT(Raw_Actuals[Month],"mmm-yy")=TEXT(EDATE(A8,-12),"mmm-yy"))*(Raw_Actuals[Account_Name]="Employee Cost")*Raw_Actuals[Amount_INR_Lakh])*(1+Budget_Assumptions!$B$3)} -> 291.5 | D8: =Data_Profiling!H59*(1+Budget_Assumptions!$B$4) -> 51.94 | E8: =Data_Profiling!H74*(1+Budget_Assumptions!$B$5) -> 33.48 | F8: =Data_Profiling!H89*(1+Budget_Assumptions!$B$6) -> 26.45 | G8: =Data_Profiling!H104*(1+Budget_Assumptions!$B$7) -> 25.68 | H8: =SUM(C8:G8) -> 429.05 | I8: =B8-H8 -> 429.99 | J8: =I8/B8 -> 0.50054712
A9: 46718 | B9: =Data_Profiling!B22*(1+Budget_Assumptions!$B$2) -> 882.56 | C9: {=SUMPRODUCT((TEXT(Raw_Actuals[Month],"mmm-yy")=TEXT(EDATE(A9,-12),"mmm-yy"))*(Raw_Actuals[Account_Name]="Employee Cost")*Raw_Actuals[Amount_INR_Lakh])*(1+Budget_Assumptions!$B$3)} -> 294.8 | D9: =Data_Profiling!H60*(1+Budget_Assumptions!$B$4) -> 51.94 | E9: =Data_Profiling!H75*(1+Budget_Assumptions!$B$5) -> 34.56 | F9: =Data_Profiling!H90*(1+Budget_Assumptions!$B$6) -> 28.75 | G9: =Data_Profiling!H105*(1+Budget_Assumptions!$B$7) -> 24.61 | H9: =SUM(C9:G9) -> 434.66 | I9: =B9-H9 -> 447.9 | J9: =I9/B9 -> 0.50750091
A10: 46748 | B10: =Data_Profiling!B23*(1+Budget_Assumptions!$B$2) -> 907.2 | C10: {=SUMPRODUCT((TEXT(Raw_Actuals[Month],"mmm-yy")=TEXT(EDATE(A10,-12),"mmm-yy"))*(Raw_Actuals[Account_Name]="Employee Cost")*Raw_Actuals[Amount_INR_Lakh])*(1+Budget_Assumptions!$B$3)} -> 297 | D10: =Data_Profiling!H61*(1+Budget_Assumptions!$B$4) -> 53 | E10: =Data_Profiling!H76*(1+Budget_Assumptions!$B$5) -> 34.56 | F10: =Data_Profiling!H91*(1+Budget_Assumptions!$B$6) -> 29.9 | G10: =Data_Profiling!H106*(1+Budget_Assumptions!$B$7) -> 25.68 | H10: =SUM(C10:G10) -> 440.14 | I10: =B10-H10 -> 467.06 | J10: =I10/B10 -> 0.51483686
A11: 46780 | B11: =Data_Profiling!B24*(1+Budget_Assumptions!$B$2) -> 929.6 | C11: {=SUMPRODUCT((TEXT(Raw_Actuals[Month],"mmm-yy")=TEXT(EDATE(A11,-12),"mmm-yy"))*(Raw_Actuals[Account_Name]="Employee Cost")*Raw_Actuals[Amount_INR_Lakh])*(1+Budget_Assumptions!$B$3)} -> 300.3 | D11: =Data_Profiling!H62*(1+Budget_Assumptions!$B$4) -> 53 | E11: =Data_Profiling!H77*(1+Budget_Assumptions!$B$5) -> 35.64 | F11: =Data_Profiling!H92*(1+Budget_Assumptions!$B$6) -> 28.75 | G11: =Data_Profiling!H107*(1+Budget_Assumptions!$B$7) -> 26.75 | H11: =SUM(C11:G11) -> 444.44 | I11: =B11-H11 -> 485.16 | J11: =I11/B11 -> 0.52190189
A12: 46811 | B12: =Data_Profiling!B25*(1+Budget_Assumptions!$B$2) -> 952 | C12: {=SUMPRODUCT((TEXT(Raw_Actuals[Month],"mmm-yy")=TEXT(EDATE(A12,-12),"mmm-yy"))*(Raw_Actuals[Account_Name]="Employee Cost")*Raw_Actuals[Amount_INR_Lakh])*(1+Budget_Assumptions!$B$3)} -> 303.6 | D12: =Data_Profiling!H63*(1+Budget_Assumptions!$B$4) -> 53 | E12: =Data_Profiling!H78*(1+Budget_Assumptions!$B$5) -> 35.64 | F12: =Data_Profiling!H93*(1+Budget_Assumptions!$B$6) -> 31.05 | G12: =Data_Profiling!H108*(1+Budget_Assumptions!$B$7) -> 25.68 | H12: =SUM(C12:G12) -> 448.97 | I12: =B12-H12 -> 503.03 | J12: =I12/B12 -> 0.52839286
A13: 46840 | B13: =Data_Profiling!B26*(1+Budget_Assumptions!$B$2) -> 996.8 | C13: {=SUMPRODUCT((TEXT(Raw_Actuals[Month],"mmm-yy")=TEXT(EDATE(A13,-12),"mmm-yy"))*(Raw_Actuals[Account_Name]="Employee Cost")*Raw_Actuals[Amount_INR_Lakh])*(1+Budget_Assumptions!$B$3)} -> 308 | D13: =Data_Profiling!H64*(1+Budget_Assumptions!$B$4) -> 54.06 | E13: =Data_Profiling!H79*(1+Budget_Assumptions!$B$5) -> 36.72 | F13: =Data_Profiling!H94*(1+Budget_Assumptions!$B$6) -> 32.2 | G13: =Data_Profiling!H109*(1+Budget_Assumptions!$B$7) -> 27.82 | H13: =SUM(C13:G13) -> 458.8 | I13: =B13-H13 -> 538 | J13: =I13/B13 -> 0.53972713
B15: FY2027 Budget Summary
B16: Total Revenue Budget | C16: =SUM(B2:B13) -> 10240.16
B17: Total OpEx Budget | C17: =SUM(H2:H13) -> 5139.38
B18: Total EBITDA Budget | C18: =SUM(I2:I13) -> 5100.78
B19: EBITDA Margin | C19: =5131.02/10240.16 -> 0.50106834
B21: Budget Reconciliation Check | C21: =SUM(B2:B13)-10240.16 -> 0
B22: OpEx Budget Reconciliation Check | C22: =SUM(H2:H13)-5139.38 -> 0
B23: EBITDA Budget Reconciliation Check | C23: =SUM(I2:I13)-C18 -> 0
B24: EBITDA Margin Reconciliation Check | C24: =SUM(I2:I13)/SUM(B2:B13)-C19 -> -0.0029530789

Sheet FY2027_Actuals
A1: Month | B1: Revenue Actual (₹ lakh) | C1: Employee Cost Actual (₹ lakh) | D1: Other OpEx Actual (₹ lakh) | E1: Total OpEx Actual (₹ lakh) | F1: EBITDA Actual (₹ lakh) | H1: OpEx Reconciliation Check | I1: EBITDA Reconciliation Check
A2: 46504 | B2: 735 | C2: 278 | D2: 245 | E2: =SUM(C2:D2) -> 523 | F2: =B2-E2 -> 212 | H2: =C2+D2-E2 -> 0 | I2: =B2-E2-F2 -> 0
A3: 46534 | B3: 765 | C3: 285 | D3: =E3-C3 -> 132 | E3: 417 | F3: =B3-E3 -> 348 | H3: =C3+D3-E3 -> 0 | I3: =B3-E3-F3 -> 0
A4: 46565 | B4: 770 | C4: 290 | D4: =E4-C4 -> 130 | E4: 420 | F4: =B4-E4 -> 350 | H4: =C4+D4-E4 -> 0 | I4: =B4-E4-F4 -> 0
A5: 46595 | B5: 810 | C5: 294 | D5: =E5-C5 -> 131 | E5: 425 | F5: =B5-E5 -> 385 | H5: =C5+D5-E5 -> 0 | I5: =B5-E5-F5 -> 0
A6: 46626 | B6: 800 | C6: 300 | D6: =E6-C6 -> 135 | E6: 435 | F6: =B6-E6 -> 365 | H6: =C6+D6-E6 -> 0 | I6: =B6-E6-F6 -> 0
A7: 46657 | B7: 855 | C7: 305 | D7: =E7-C7 -> 134 | E7: 439 | F7: =B7-E7 -> 416 | H7: =C7+D7-E7 -> 0 | I7: =B7-E7-F7 -> 0
A8: 46687 | B8: 845 | C8: 310 | D8: =E8-C8 -> 138 | E8: 448 | F8: =B8-E8 -> 397 | H8: =C8+D8-E8 -> 0 | I8: =B8-E8-F8 -> 0
A9: 46718 | B9: 900 | C9: 315 | D9: =E9-C9 -> 140 | E9: 455 | F9: =B9-E9 -> 445 | H9: =C9+D9-E9 -> 0 | I9: =B9-E9-F9 -> 0
A10: 46748 | B10: 925 | C10: 320 | D10: =E10-C10 -> 150 | E10: 470 | F10: =B10-E10 -> 455 | H10: =C10+D10-E10 -> 0 | I10: =B10-E10-F10 -> 0
A11: 46779 | B11: 915 | C11: 325 | D11: =E11-C11 -> 143 | E11: 468 | F11: =B11-E11 -> 447 | H11: =C11+D11-E11 -> 0 | I11: =B11-E11-F11 -> 0
A12: 46810 | B12: 970 | C12: 330 | D12: =E12-C12 -> 150 | E12: 480 | F12: =B12-E12 -> 490 | H12: =C12+D12-E12 -> 0 | I12: =B12-E12-F12 -> 0
A13: 46839 | B13: 1020 | C13: 338 | D13: =E13-C13 -> 152 | E13: 490 | F13: =B13-E13 -> 530 | H13: =C13+D13-E13 -> 0 | I13: =B13-E13-F13 -> 0

Sheet Actual_vs_Budget
A1: Month | B1: Revenue Actual (₹ lakh) | C1: Revenue Budget (₹ lakh) | D1: Revenue Variance (₹ lakh) | E1: Revenue Variance % | F1: OpEx Actual (₹ lakh) | G1: OpEx Budget (₹ lakh) | H1: OpEx Variance (₹ lakh) | I1: OpEx Variance % | J1: EBITDA Actual (₹ lakh) | K1: EBITDA Budget (₹ lakh) | L1: EBITDA Variance (₹ lakh) | M1: EBITDA Variance % | O1: Management Summary | P1: Value
A2: =FY2027_Actuals!A2 -> 46504 | B2: =FY2027_Actuals!B2 -> 735 | C2: =FY2027_Budget!B2 -> 728 | D2: =IF(B2="","",B2-C2) -> 7 | E2: =IF(B2="","",D2/C2) -> 0.0096153846 | F2: 523 | G2: =FY2027_Budget!H2 -> 400.36 | H2: =IF(F2="","",F2-G2) -> 122.64 | I2: =IF(F2="","",H2/G2) -> 0.30632431 | J2: =B2-F2 -> 212 | K2: =FY2027_Budget!I2 -> 327.64 | L2: =IF(J2="","",J2-K2) -> -115.64 | M2: =IF(J2="","",L2/K2) -> -0.35294836 | O2: Revenue Budget | P2: =SUM(C2:C13) -> 10240.16
A3: =FY2027_Actuals!A3 -> 46534 | B3: 765 | C3: =FY2027_Budget!B3 -> 756 | D3: =IF(B3="","",B3-C3) -> 9 | E3: =IF(B3="","",D3/C3) -> 0.011904762 | F3: 417 | G3: =FY2027_Budget!H3 -> 404.87 | H3: =IF(F3="","",F3-G3) -> 12.13 | I3: =IF(F3="","",H3/G3) -> 0.029960234 | J3: =B3-F3 -> 348 | K3: =FY2027_Budget!I3 -> 351.13 | L3: =IF(J3="","",J3-K3) -> -3.13 | M3: =IF(J3="","",L3/K3) -> -0.0089140774 | O3: OpEx Budget | P3: =SUM(G2:G13) -> 5139.38
A4: =FY2027_Actuals!A4 -> 46565 | B4: 770 | C4: =FY2027_Budget!B4 -> 781.76 | D4: =IF(B4="","",B4-C4) -> -11.76 | E4: =IF(B4="","",D4/C4) -> -0.01504298 | F4: 420 | G4: =FY2027_Budget!H4 -> 417.07 | H4: =IF(F4="","",F4-G4) -> 2.93 | I4: =IF(F4="","",H4/G4) -> 0.0070251996 | J4: =B4-F4 -> 350 | K4: =FY2027_Budget!I4 -> 364.69 | L4: =IF(J4="","",J4-K4) -> -14.69 | M4: =IF(J4="","",L4/K4) -> -0.040280786 | O4: EBITDA Budget | P4: =SUM(K2:K13) -> 5100.78
A5: =FY2027_Actuals!A5 -> 46595 | B5: 810 | C5: =FY2027_Budget!B5 -> 795.2 | D5: =IF(B5="","",B5-C5) -> 14.8 | E5: =IF(B5="","",D5/C5) -> 0.01861167 | F5: 425 | G5: =FY2027_Budget!H5 -> 415.92 | H5: =IF(F5="","",F5-G5) -> 9.08 | I5: =IF(F5="","",H5/G5) -> 0.021831121 | J5: =B5-F5 -> 385 | K5: =FY2027_Budget!I5 -> 379.28 | L5: =IF(J5="","",J5-K5) -> 5.72 | M5: =IF(J5="","",L5/K5) -> 0.015081206 | O5: EBITDA Margin | P5: =P4/P2 -> 0.49811526
A6: =FY2027_Actuals!A6 -> 46626 | B6: 800 | C6: =FY2027_Budget!B6 -> 814.24 | D6: =IF(B6="","",B6-C6) -> -14.24 | E6: =IF(B6="","",D6/C6) -> -0.017488701 | F6: 435 | G6: =FY2027_Budget!H6 -> 420.34 | H6: =IF(F6="","",F6-G6) -> 14.66 | I6: =IF(F6="","",H6/G6) -> 0.034876529 | J6: =B6-F6 -> 365 | K6: =FY2027_Budget!I6 -> 393.9 | L6: =IF(J6="","",J6-K6) -> -28.9 | M6: =IF(J6="","",L6/K6) -> -0.073368875 | O6: Revenue Variance
A7: =FY2027_Actuals!A7 -> 46657 | B7: 855 | C7: =FY2027_Budget!B7 -> 837.76 | D7: =IF(B7="","",B7-C7) -> 17.24 | E7: =IF(B7="","",D7/C7) -> 0.020578686 | F7: 439 | G7: =FY2027_Budget!H7 -> 424.76 | H7: =IF(F7="","",F7-G7) -> 14.24 | I7: =IF(F7="","",H7/G7) -> 0.033524814 | J7: =B7-F7 -> 416 | K7: =FY2027_Budget!I7 -> 413 | L7: =IF(J7="","",J7-K7) -> 3 | M7: =IF(J7="","",L7/K7) -> 0.0072639225 | O7: EBITDA Variance
A8: =FY2027_Actuals!A8 -> 46687 | B8: 845 | C8: =FY2027_Budget!B8 -> 859.04 | D8: =IF(B8="","",B8-C8) -> -14.04 | E8: =IF(B8="","",D8/C8) -> -0.016343826 | F8: 448 | G8: =FY2027_Budget!H8 -> 429.05 | H8: =IF(F8="","",F8-G8) -> 18.95 | I8: =IF(F8="","",H8/G8) -> 0.044167346 | J8: =B8-F8 -> 397 | K8: =FY2027_Budget!I8 -> 429.99 | L8: =IF(J8="","",J8-K8) -> -32.99 | M8: =IF(J8="","",L8/K8) -> -0.076722714
A9: =FY2027_Actuals!A9 -> 46718 | B9: 900 | C9: =FY2027_Budget!B9 -> 882.56 | D9: =IF(B9="","",B9-C9) -> 17.44 | E9: =IF(B9="","",D9/C9) -> 0.019760696 | F9: 455 | G9: =FY2027_Budget!H9 -> 434.66 | H9: =IF(F9="","",F9-G9) -> 20.34 | I9: =IF(F9="","",H9/G9) -> 0.046795196 | J9: =B9-F9 -> 445 | K9: =FY2027_Budget!I9 -> 447.9 | L9: =IF(J9="","",J9-K9) -> -2.9 | M9: =IF(J9="","",L9/K9) -> -0.0064746595
A10: =FY2027_Actuals!A10 -> 46748 | B10: 925 | C10: =FY2027_Budget!B10 -> 907.2 | D10: =IF(B10="","",B10-C10) -> 17.8 | E10: =IF(B10="","",D10/C10) -> 0.019620811 | F10: 470 | G10: =FY2027_Budget!H10 -> 440.14 | H10: =IF(F10="","",F10-G10) -> 29.86 | I10: =IF(F10="","",H10/G10) -> 0.06784205 | J10: =B10-F10 -> 455 | K10: =FY2027_Budget!I10 -> 467.06 | L10: =IF(J10="","",J10-K10) -> -12.06 | M10: =IF(J10="","",L10/K10) -> -0.025821094 | O10: FY2027 Management Analysis | R10: Expense Category | S10: Actual | T10: Budget | U10: Variance
A11: =FY2027_Actuals!A11 -> 46779 | B11: 915 | C11: =FY2027_Budget!B11 -> 929.6 | D11: =IF(B11="","",B11-C11) -> -14.6 | E11: =IF(B11="","",D11/C11) -> -0.01570568 | F11: 468 | G11: =FY2027_Budget!H11 -> 444.44 | H11: =IF(F11="","",F11-G11) -> 23.56 | I11: =IF(F11="","",H11/G11) -> 0.05301053 | J11: =B11-F11 -> 447 | K11: =FY2027_Budget!I11 -> 485.16 | L11: =IF(J11="","",J11-K11) -> -38.16 | M11: =IF(J11="","",L11/K11) -> -0.078654465 | O11: Total Revenue Actual | P11: =SUM(B2:B13) -> 10310 | R11: Employee Cost | S11: =FY2027_Actuals!C2 -> 278 | T11: =FY2027_Budget!C2 -> 275 | U11: =S11-T11 -> 3
A12: =FY2027_Actuals!A12 -> 46810 | B12: 970 | C12: =FY2027_Budget!B12 -> 952 | D12: =IF(B12="","",B12-C12) -> 18 | E12: =IF(B12="","",D12/C12) -> 0.018907563 | F12: 480 | G12: =FY2027_Budget!H12 -> 448.97 | H12: =IF(F12="","",F12-G12) -> 31.03 | I12: =IF(F12="","",H12/G12) -> 0.069113749 | J12: =B12-F12 -> 490 | K12: =FY2027_Budget!I12 -> 503.03 | L12: =IF(J12="","",J12-K12) -> -13.03 | M12: =IF(J12="","",L12/K12) -> -0.025903028 | O12: Total Revenue Budget | P12: =SUM(C2:C13) -> 10240.16 | R12: Other OpEx | S12: =FY2027_Actuals!D2 -> 245 | T12: =FY2027_Budget!D2+FY2027_Budget!E2+FY2027_Budget!F2+FY2027_Budget!G2 -> 125.36 | U12: =S12-T12 -> 119.64
A13: =FY2027_Actuals!A13 -> 46839 | B13: 1020 | C13: =FY2027_Budget!B13 -> 996.8 | D13: =IF(B13="","",B13-C13) -> 23.2 | E13: =IF(B13="","",D13/C13) -> 0.023274478 | F13: 490 | G13: =FY2027_Budget!H13 -> 458.8 | H13: =IF(F13="","",F13-G13) -> 31.2 | I13: =IF(F13="","",H13/G13) -> 0.068003487 | J13: =B13-F13 -> 530 | K13: =FY2027_Budget!I13 -> 538 | L13: =IF(J13="","",J13-K13) -> -8 | M13: =IF(J13="","",L13/K13) -> -0.014869888 | O13: Revenue Variance | P13: =P11-P12 -> 69.84 | R13: Total | S13: =SUM(S11:S12) -> 523 | T13: =SUM(T11:T12) -> 400.36 | U13: =SUM(U11:U12) -> 122.64
O14: Revenue Variance % | P14: =P13/P12 -> 0.0068202059
O15: Total OpEx Actual | P15: =SUM(F2:F13) -> 5470
O16: Total OpEx Budget | P16: =SUM(G2:G13) -> 5139.38
O17: OpEx Variance | P17: =P15-P16 -> 330.62
O18: OpEx Variance % | P18: =P17/P16 -> 0.064330717
R20: Expense Category | S20: Actual | T20: Budget | U20: Variance
O21: Total EBITDA Actual | P21: =SUM(J2:J13) -> 4840 | R21: Rent & Utilities | S21: 52 | T21: =FY2027_Budget!D2 -> 50.88 | U21: =S21-T21 -> 1.12
O22: Total EBITDA Budget | P22: =SUM(K2:K13) -> 5100.78 | R22: Software Licenses | S22: 31 | T22: =FY2027_Budget!E2 -> 30.24 | U22: =S22-T22 -> 0.76
O23: EBITDA Variance | P23: =P21-P22 -> -260.78
O24: EBITDA Variance % | P24: =P23/P22 -> -0.051125514
O26: Management Commentary
O27: Revenue was ₹69.84 lakh above budget, representing approximately 0.7% favorable variance.
O28: Operating expenses were ₹330.62 lakh above budget, representing approximately 6.4% unfavorable variance.
O29: Higher operating expenses more than offset the favorable revenue variance, resulting in EBITDA being ₹260.78 lakh below budget.
O30: Management should investigate the key operating expense drivers and determine whether the unfavorable variance is temporary or structural.
O33: Monthly EBITDA Analysis
O34: Month | P34: EBITDA Actual | Q34: EBITDA Budget | R34: EBITDA Variance
O35: =A2 -> 46504 | P35: =J2 -> 212 | Q35: =K2 -> 327.64 | R35: =L2 -> -115.64
O36: =A3 -> 46534 | P36: =J3 -> 348 | Q36: =K3 -> 351.13 | R36: =L3 -> -3.13
O37: =A4 -> 46565 | P37: =J4 -> 350 | Q37: =K4 -> 364.69 | R37: =L4 -> -14.69
O38: =A5 -> 46595 | P38: =J5 -> 385 | Q38: =K5 -> 379.28 | R38: =L5 -> 5.72
O39: =A6 -> 46626 | P39: =J6 -> 365 | Q39: =K6 -> 393.9 | R39: =L6 -> -28.9
O40: =A7 -> 46657 | P40: =J7 -> 416 | Q40: =K7 -> 413 | R40: =L7 -> 3
O41: =A8 -> 46687 | P41: =J8 -> 397 | Q41: =K8 -> 429.99 | R41: =L8 -> -32.99
O42: =A9 -> 46718 | P42: =J9 -> 445 | Q42: =K9 -> 447.9 | R42: =L9 -> -2.9
O43: =A10 -> 46748 | P43: =J10 -> 455 | Q43: =K10 -> 467.06 | R43: =L10 -> -12.06
O44: =A11 -> 46779 | P44: =J11 -> 447 | Q44: =K11 -> 485.16 | R44: =L11 -> -38.16
...

Sheet FP&A Dashboard
A1: XYZCompany – FY2027 FP&A Executive Dashboard
A3: Actual vs Budget Performance | Apr-2027 to Mar-2028
A5: Revenue Actual (₹ lakh) | D5: Operating Expenses Actual (₹ lakh) | G5: EBITDA Actual (₹ lakh) | J5: EBITDA Margin Actual
A6: =Actual_vs_Budget!P11 -> 10310 | D6: =Actual_vs_Budget!P15 -> 5470 | G6: =Actual_vs_Budget!P21 -> 4840 | J6: =Actual_vs_Budget!P21/Actual_vs_Budget!P11 -> 0.46944714
A23: Management Insights
A24: Revenue: Actual revenue was ₹10,310L, ₹69.84L above budget.
A25: Operating Expenses: Actual OpEx was ₹5,470L, ₹330.62L above budget.
A26: EBITDA: Actual EBITDA was ₹4,840L, ₹260.78L below budget.
A27: Key Driver: April OpEx was ₹122.64L above budget, primarily driven by Other Operating Expenses.

Sheet Model_Assumptions
A1: XYZCompany – Financial Model Assumptions
A2: FY2028 Forecast & Scenario Planning
A4: Assumption | B4: Value | C4: Unit
A5: Revenue Growth | B5: 0.12 | C5: %
A6: Employee Cost Growth | B6: 0.1 | C6: %
A7: Rent & Utilities Growth | B7: 0.08 | C7: %
A8: Software Licenses Growth | B8: 0.06 | C8: %
A9: Travel & Sales Expense Growth | B9: 0.15 | C9: %
A10: Other Administrative Expense Growth | B10: 0.07 | C10: %
A11: Tax Rate | B11: 0.25 | C11: %
A12: Capex Growth | B12: 0.08 | C12: %
A13: Working Capital % of Revenue | B13: 0.05 | C13: %

Sheet Revenue_Model
A1: XYZCompany – Revenue Model
A2: FY2028 Revenue Forecast
A4: Business Unit | B4: FY2027 Actual Revenue (₹ lakh) | C4: Growth Assumption | D4: FY2028 Forecast Revenue (₹ lakh) | E4: Revenue Contribution %
A5: Software Solutions | B5: =Data_Profiling!H3 -> 4520 | C5: 0.1 | D5: =B5*(1+C5) -> 4972 | E5: =D5/$D$8 -> 0.47897731
A6: Data Analytics | B6: =Data_Profiling!H4 -> 2783 | C6: 0.15 | D6: =B6*(1+C6) -> 3200.45 | E6: =D6/$D$8 -> 0.30831515
A7: Cloud Services | B7: =Data_Profiling!H5 -> 1840 | C7: 0.2 | D7: =B7*(1+C7) -> 2208 | E7: =D7/$D$8 -> 0.21270754
A8: Total Revenue | B8: =SUM(B5:B7) -> 9143 | D8: =SUM(D5:D7) -> 10380.45 | E8: =SUM(E5:E7) -> 1
A10: FY2028 Revenue Growth | B10: =(D8-B8)/B8 -> 0.13534398

Sheet Cost_Model
A1: XYZCompany – Cost Model
A2: FY2028 Operating Expense Forecast
A4: FY2027 Actual (₹ lakh) | B4: Growth Assumption | C4: FY2028 Forecast (₹ lakh) | D4: % of Revenue | E4: Total OpEx %
A5: Employee Cost | B5: =Data_Profiling!B38 -> 3169 | C5: =Model_Assumptions!B6 -> 0.1 | D5: =B5*(1+C5) -> 3485.9 | E5: =D5/Revenue_Model!$D$8 -> 0.33581396
A6: Rent & Utilities | B6: =Data_Profiling!B40 -> 588 | C6: =Model_Assumptions!B7 -> 0.08 | D6: =B6*(1+C6) -> 635.04 | E6: =D6/Revenue_Model!$D$8 -> 0.061176539
A7: Software Licenses | B7: =Data_Profiling!B42 -> 374 | C7: =Model_Assumptions!B8 -> 0.06 | D7: =B7*(1+C7) -> 396.44 | E7: =D7/Revenue_Model!$D$8 -> 0.038191023
A8: Travel & Sales Expense | B8: =Data_Profiling!B44 -> 285 | C8: =Model_Assumptions!B9 -> 0.15 | D8: =B8*(1+C8) -> 327.75 | E8: =D8/Revenue_Model!$D$8 -> 0.031573776
A9: Other Administrative Expense | B9: =Data_Profiling!B46 -> 279 | C9: =Model_Assumptions!B10 -> 0.07 | D9: =B9*(1+C9) -> 298.53 | E9: =D9/Revenue_Model!$D$8 -> 0.028758869
A10: Total Operating Expenses | B10: =SUM(B5:B9) -> 4695 | D10: =SUM(D5:D9) -> 5143.66 | E10: =SUM(E5:E9) -> 0.49551416
A12: Operating Cost Analysis
A13: Employee Cost as % of OpEx | B13: =D5/D10 -> 0.67770809
A14: Non-Employee OpEx | B14: =D10-D5 -> 1657.76
A15: Total OpEx as % of Revenue | B15: =D10/Revenue_Model!$D$8 -> 0.49551416
A17: FY2028 EBITDA Forecast
A18: Revenue | B18: =Revenue_Model!D8 -> 10380.45
A19: Total Operating Expenses | B19: =D10 -> 5143.66
A20: EBITDA | B20: =B18-B19 -> 5236.79
A21: EBITDA Margin | B21: =B20/B18 -> 0.50448584
G25: FY2028 EBITDA Forecast
G26: Revenue
G27: Total Operating Expenses
G28: EBITDA
G29: EBITDA Margin

Sheet P&L_Forecast
A1: XYZCompany – P&L Forecast
A2: FY2028 Income Statement
A4: Line Item | B4: FY2028 Forecast (₹ lakh)
A5: Revenue | B5: =Revenue_Model!D8 -> 10380.45
A6: Operating Expenses | B6: =Cost_Model!D10 -> 5143.66
A7: EBITDA | B7: =B5-B6 -> 5236.79
A8: EBITDA Margin | B8: =B7/B5 -> 0.50448584
A10: Depreciation & Amortization | B10: 300
A11: EBIT | B11: =B7-B10 -> 4936.79
A12: EBIT Margin | B12: =B11/B5 -> 0.47558536
A14: Interest Expense | B14: 100
A15: PBT | B15: =B11-B14 -> 4836.79
A16: Tax Expense | B16: =B15*25/100 -> 1209.1975
A17: Net Profit | B17: =B15-B16 -> 3627.5925
A18: Net Profit Margin | B18: =B17/B5 -> 0.3494639

Sheet Cash_Flow
A1: XYZCompany – Cash Flow Forecast
A2: FY2028 Cash Flow Statement
A4: Line Item | B4: FY2028 Forecast (₹ lakh)
A6: Net Profit | B6: ='P&L_Forecast'!B17 -> 3627.5925
A7: Depreciation & Amortization | B7: 300
A8: Change in Working Capital | B8: =Revenue_Model!D8*Model_Assumptions!B13 -> 519.0225
A9: Cash Flow from Operating Activities | B9: =B6+B7-B8 -> 3408.57
A11: Capital Expenditure | B11: =-500*(1+Model_Assumptions!B12) -> -540
A12: Cash Flow from Investing Activities | B12: =B11 -> -540
A14: Debt / Borrowings | B14: 300
A15: Equity / Financing | B15: 0
A16: Cash Flow from Financing Activities | B16: 300
A18: Net Change in Cash | B18: =B9+B12+B16 -> 3168.57
A20: Opening Cash Balance | B20: 1000
A21: Closing Cash Balance | B21: =B20+B18 -> 4168.57

Sheet Balance Sheet
A1: XYZCompany – Balance Sheet
A2: FY2028 Balance Sheet
A4: Line Item | B4: FY2028 Forecast (₹ lakh)
A6: ASSETS
A8: Cash & Cash Equivalents | B8: =Cash_Flow!B21 -> 4168.57
A9: Accounts Receivable | B9: =Revenue_Model!D8*Model_Assumptions!B13 -> 519.0225
A10: Other Current Assets | B10: =100 -> 100
A11: Total Current Assets | B11: =SUM(B8:B10) -> 4787.5925
A13: Property | B13: =2500+ABS(Cash_Flow!B11)-'P&L_Forecast'!B10 -> 2740
A14: Other Non-Current Assets | B14: =200 -> 200
A15: Total Non-Current Assets | B15: =SUM(B13:B14) -> 2940
A17: Total Assets | B17: =B11+B15 -> 7727.5925
A19: LIABILITIES & EQUITY
A21: Accounts Payable | B21: =Revenue_Model!D8*Model_Assumptions!B13 -> 519.0225
A22: Other Current Liabilities | B22: =100 -> 100
A23: Total Current Liabilities | B23: =SUM(B21:B22) -> 619.0225
A25: Debt / Borrowings | B25: =Cash_Flow!B14 -> 300
A26: Other Non-Current Liabilities | B26: 100
A27: Total Non-Current Liabilities | B27: =SUM(B25:B26) -> 400
A29: Total Liabilities | B29: =B23+B27 -> 1019.0225
A31: Shareholders' Equity | B31: =B17-B29-B32 -> 3080.9775
A32: Retained Earnings | B32: ='P&L_Forecast'!B17 -> 3627.5925
A33: Total Equity | B33: =SUM(B31:B32) -> 6708.57
A35: Total Liabilities & Equity | B35: =B29+B33 -> 7727.5925
A37: Balance Check | B37: =B17-B35 -> 0

Sheet 3-Statement Model
A1: XYZCompany – 3-Statement Model
A2: FY2028 Integrated Financial Model
A4: Line Item | B4: FY2028 Forecast (₹ lakh)
A6: INCOME STATEMENT
A8: Revenue | B8: ='P&L_Forecast'!B5 -> 10380.45
A9: EBITDA | B9: ='P&L_Forecast'!B7 -> 5236.79
A10: EBIT | B10: ='P&L_Forecast'!B11 -> 4936.79
A11: PBT | B11: ='P&L_Forecast'!B15 -> 4836.79
A12: Net Profit | B12: ='P&L_Forecast'!B17 -> 3627.5925
A14: CASH FLOW STATEMENT
A16: Cash Flow from Operating Activities | B16: 3408.57
A17: Cash Flow from Investing Activities | B17: -540
A18: Cash Flow from Financing Activities | B18: 300
A19: Net Change in Cash | B19: 3168.57
A20: Closing Cash Balance | B20: 4168.57
A22: BALANCE SHEET
A24: Total Assets | B24: 7727.59
A25: Total Liabilities | B25: 1019.02
A26: Total Equity | B26: 6708.57
A27: Balance Check | B27: =B26+B25-B24 -> 0
A29: KEY FINANCIAL METRICS
A31: EBITDA Margin | B31: 0.504
A32: EBIT Margin | B32: 0.476
A33: Net Profit Margin | B33: 0.35

Sheet Scenario Analysis
A1: XYZCompany – Scenario Analysis
A2: FY2028 Scenario Planning
A4: Metric | B4: Base Case | C4: Upside Case | D4: Downside Case
A6: Revenue Growth | B6: 0.12 | C6: 0.18 | D6: 0.06
A7: Employee Cost Growth | B7: 0.1 | C7: 0.08 | D7: 0.14
A8: Other OpEx Growth | B8: 0.08 | C8: 0.05 | D8: 0.12
A10: Revenue (₹ lakh) | B10: =Revenue_Model!B8*(1+B6) -> 10240.16 | C10: =Revenue_Model!B8*(1+C6) -> 10788.74 | D10: =Revenue_Model!B8*(1+D6) -> 9691.58
A11: Operating Expenses (₹ lakh) | B11: =Data_Profiling!B38*(1+B7)+(Data_Profiling!B47-Data_Profiling!B38)*(1+B8) -> 5133.98 | C11: =Data_Profiling!B38*(1+C7)+(Data_Profiling!B47-Data_Profiling!B38)*(1+C8) -> 5024.82 | D11: =Data_Profiling!B38*(1+D7)+(Data_Profiling!B47-Data_Profiling!B38)*(1+D8) -> 5321.78
A12: EBITDA (₹ lakh) | B12: =B10-B11 -> 5106.18 | C12: =C10-C11 -> 5763.92 | D12: =D10-D11 -> 4369.8
A13: EBITDA Margin | B13: =B12/B10 -> 0.4986426 | C13: =C12/C10 -> 0.5342533 | D13: =D12/D10 -> 0.45088623
A14: Net Profit (₹ lakh) | B14: =(B12-300-100)*75/100 -> 3529.635 | C14: =(C12-300-100)*75/100 -> 4022.94 | D14: =(D12-300-100)*75/100 -> 2977.35
A15: Net Profit Margin | B15: =B14/B10 -> 0.34468553 | C15: =C14/C10 -> 0.37288321 | D15: =D14/D10 -> 0.30720997
A17: Scenario Impact
A19: Revenue vs Base (₹ lakh) | B19: =0 -> 0 | C19: =C10-B10 -> 548.58 | D19: =D10-B10 -> -548.58
A20: EBITDA vs Base (₹ lakh) | B20: =0 -> 0 | C20: =C12-B12 -> 657.74 | D20: =D12-B12 -> -736.38
A21: Net Profit vs Base (₹ lakh) | B21: =0 -> 0 | C21: =C14-B14 -> 493.305 | D21: =D14-B14 -> -552.285

Sheet DCF_Valuation
A1: XYZCompany – DCF Valuation
A2: FY2028 DCF Valuation
A4: DCF Assumptions | B4: Value
A6: WACC | B6: =10% -> 0.1
A7: Terminal Growth Rate | B7: =3% -> 0.03
A8: Tax Rate | B8: =Model_Assumptions!B11 -> 0.25
A10: FCFF Forecast
A12: Line Item | B12: FY2028 Forecast (₹ lakh)
A13: EBIT | B13: ='P&L_Forecast'!B11 -> 4936.79
A14: Tax on EBIT | B14: =B13*B8 -> 1234.1975
A15: NOPAT | B15: =B13-B14 -> 3702.5925
A16: Depreciation & Amortization | B16: ='P&L_Forecast'!B10 -> 300
A17: Capital Expenditure | B17: =ABS(Cash_Flow!B11) -> 540
A18: Change in Working Capital | B18: =Revenue_Model!D8*Model_Assumptions!B13 -> 519.0225
A19: Free Cash Flow to Firm (FCFF) | B19: =B15+B16-B17-B18 -> 2943.57
A21: Valuation
A23: Present Value of FCFF | B23: =B19/(1+$B$6)^1 -> 2675.9727
A24: Terminal Value | B24: =B19*(1+$B$7)/($B$6-$B$7) -> 43312.53
A25: Present Value of Terminal Value | B25: =B24/(1+$B$6)^1 -> 39375.027
A26: Enterprise Value | B26: =B23+B25 -> 42051
A27: Less: Debt | B27: =Cash_Flow!B14 -> 300
A28: Add: Cash | B28: =Cash_Flow!B21 -> 4168.57
A29: Equity Value | B29: =B26-B27+B28 -> 45919.57

Sheet DCF_Sensitivity
A1: XYZCompany – DCF Sensitivity Analysis
A2: FY2028 DCF Valuation Sensitivity
A4: Equity Value Sensitivity (₹ lakh)
A6: Terminal Growth Rate →/WACC ↓ | B6: 0.02 | C6: 0.025 | D6: 0.03 | E6: 0.035 | F6: 0.04
A7: 0.09 | B7: =(DCF_Valuation!$B$19/(1+$A7))+(((DCF_Valuation!$B$19*(1+B$6))/($A7-B$6))/(1+$A7))-DCF_Valuation!$B$27+DCF_Valuation!$B$28 -> 45919.57 | C7: =(DCF_Valuation!$B$19/(1+$A7))+(((DCF_Valuation!$B$19*(1+C$6))/($A7-C$6))/(1+$A7))-DCF_Valuation!$B$27+DCF_Valuation!$B$28 -> 49154.262 | D7: =(DCF_Valuation!$B$19/(1+$A7))+(((DCF_Valuation!$B$19*(1+D$6))/($A7-D$6))/(1+$A7))-DCF_Valuation!$B$27+DCF_Valuation!$B$28 -> 52928.07 | E7: =(DCF_Valuation!$B$19/(1+$A7))+(((DCF_Valuation!$B$19*(1+E$6))/($A7-E$6))/(1+$A7))-DCF_Valuation!$B$27+DCF_Valuation!$B$28 -> 57388.025 | F7: =(DCF_Valuation!$B$19/(1+$A7))+(((DCF_Valuation!$B$19*(1+F$6))/($A7-F$6))/(1+$A7))-DCF_Valuation!$B$27+DCF_Valuation!$B$28 -> 62739.97
A8: 0.095 | B8: =(DCF_Valuation!$B$19/(1+$A8))+(((DCF_Valuation!$B$19*(1+B$6))/($A8-B$6))/(1+$A8))-DCF_Valuation!$B$27+DCF_Valuation!$B$28 -> 43116.17 | C8: =(DCF_Valuation!$B$19/(1+$A8))+(((DCF_Valuation!$B$19*(1+C$6))/($A8-C$6))/(1+$A8))-DCF_Valuation!$B$27+DCF_Valuation!$B$28 -> 45919.57 | D8: =(DCF_Valuation!$B$19/(1+$A8))+(((DCF_Valuation!$B$19*(1+D$6))/($A8-D$6))/(1+$A8))-DCF_Valuation!$B$27+DCF_Valuation!$B$28 -> 49154.262 | E8: =(DCF_Valuation!$B$19/(1+$A8))+(((DCF_Valuation!$B$19*(1+E$6))/($A8-E$6))/(1+$A8))-DCF_Valuation!$B$27+DCF_Valuation!$B$28 -> 52928.07 | F8: =(DCF_Valuation!$B$19/(1+$A8))+(((DCF_Valuation!$B$19*(1+F$6))/($A8-F$6))/(1+$A8))-DCF_Valuation!$B$27+DCF_Valuation!$B$28 -> 57388.025
A9: 0.1 | B9: =(DCF_Valuation!$B$19/(1+$A9))+(((DCF_Valuation!$B$19*(1+B$6))/($A9-B$6))/(1+$A9))-DCF_Valuation!$B$27+DCF_Valuation!$B$28 -> 40663.195 | C9: =(DCF_Valuation!$B$19/(1+$A9))+(((DCF_Valuation!$B$19*(1+C$6))/($A9-C$6))/(1+$A9))-DCF_Valuation!$B$27+DCF_Valuation!$B$28 -> 43116.17 | D9: =(DCF_Valuation!$B$19/(1+$A9))+(((DCF_Valuation!$B$19*(1+D$6))/($A9-D$6))/(1+$A9))-DCF_Valuation!$B$27+DCF_Valuation!$B$28 -> 45919.57 | E9: =(DCF_Valuation!$B$19/(1+$A9))+(((DCF_Valuation!$B$19*(1+E$6))/($A9-E$6))/(1+$A9))-DCF_Valuation!$B$27+DCF_Valuation!$B$28 -> 49154.262 | F9: =(DCF_Valuation!$B$19/(1+$A9))+(((DCF_Valuation!$B$19*(1+F$6))/($A9-F$6))/(1+$A9))-DCF_Valuation!$B$27+DCF_Valuation!$B$28 -> 52928.07
A10: 0.105 | B10: =(DCF_Valuation!$B$19/(1+$A10))+(((DCF_Valuation!$B$19*(1+B$6))/($A10-B$6))/(1+$A10))-DCF_Valuation!$B$27+DCF_Valuation!$B$28 -> 38498.805 | C10: =(DCF_Valuation!$B$19/(1+$A10))+(((DCF_Valuation!$B$19*(1+C$6))/($A10-C$6))/(1+$A10))-DCF_Valuation!$B$27+DCF_Valuation!$B$28 -> 40663.195 | D10: =(DCF_Valuation!$B$19/(1+$A10))+(((DCF_Valuation!$B$19*(1+D$6))/($A10-D$6))/(1+$A10))-DCF_Valuation!$B$27+DCF_Valuation!$B$28 -> 43116.17 | E10: =(DCF_Valuation!$B$19/(1+$A10))+(((DCF_Valuation!$B$19*(1+E$6))/($A10-E$6))/(1+$A10))-DCF_Valuation!$B$27+DCF_Valuation!$B$28 -> 45919.57 | F10: =(DCF_Valuation!$B$19/(1+$A10))+(((DCF_Valuation!$B$19*(1+F$6))/($A10-F$6))/(1+$A10))-DCF_Valuation!$B$27+DCF_Valuation!$B$28 -> 49154.262
A11: 0.11 | B11: =(DCF_Valuation!$B$19/(1+$A11))+(((DCF_Valuation!$B$19*(1+B$6))/($A11-B$6))/(1+$A11))-DCF_Valuation!$B$27+DCF_Valuation!$B$28 -> 36574.903 | C11: =(DCF_Valuation!$B$19/(1+$A11))+(((DCF_Valuation!$B$19*(1+C$6))/($A11-C$6))/(1+$A11))-DCF_Valuation!$B$27+DCF_Valuation!$B$28 -> 38498.805 | D11: =(DCF_Valuation!$B$19/(1+$A11))+(((DCF_Valuation!$B$19*(1+D$6))/($A11-D$6))/(1+$A11))-DCF_Valuation!$B$27+DCF_Valuation!$B$28 -> 40663.195 | E11: =(DCF_Valuation!$B$19/(1+$A11))+(((DCF_Valuation!$B$19*(1+E$6))/($A11-E$6))/(1+$A11))-DCF_Valuation!$B$27+DCF_Valuation!$B$28 -> 43116.17 | F11: =(DCF_Valuation!$B$19/(1+$A11))+(((DCF_Valuation!$B$19*(1+F$6))/($A11-F$6))/(1+$A11))-DCF_Valuation!$B$27+DCF_Valuation!$B$28 -> 45919.57
A13: Base Case Assumptions
A15: WACC | B15: 0.1
A16: Terminal Growth Rate | B16: 0.03
A17: Base Equity Value | B17: 45919.57
